## 2-2. 예외 객체와 throw구문

**예외 객체**는 try-catch 구문에서 catch 괄호 안에 입력하는 식별자이다. e, exception 등의 변수명으로 표현하며 예외 정보를 담고 있다.

예외 객체의 기본 속성은 name, message 이다.

```jsx
try {
	  const snack = '과자'; 
		snack = '음료수';
} catch(exception) {
	  console.log(`예외 이름 : ${exception.name}`);
	  console.log(`에외 메시지 : ${exception.message}`);
}
```

<img src="https://www.notion.so/image/https%3A%2F%2Fs3-us-west-2.amazonaws.com%2Fsecure.notion-static.com%2Fbc4becd9-9409-43c6-8957-001f759728bf%2FUntitled.png?table=block&id=49a09c1c-3ea0-44b4-93c8-98d615225216&spaceId=ec0d7739-bd01-43d1-8129-07440e8072b9&width=960&userId=19057883-22e4-4932-94d9-95a8802de2c0&cache=v2">

`const`로 선언한 `snack` 변수에 다른 값을 넣는 경우 `TypeError`가 발생하고 그에 따른 설명이 메시지로 나오는 것을 볼 수 있다.

`**throw` 구문**은 사용자가 정의한 예외를 강제로 발생시킬 때 사용한다. 예외가 발생하면 현재 실행되고 있던 동작이 중지되고 throw 호출자 함수 사이에 catch 블록이 실행되며 없다면 종료된다. throw로 예외를 사용할 때는 throw 다음에 `String, Number, Boolean type` 과 `Object` 도 가능하다.

```jsx
function getSnack(snack) {
    if (snack !== 0)
				return 10/snack;
    else
        throw 'snack 없음!';
}

try {
    let snack = 0;
    getSnack(snack);
} catch (e) {
    console.log(e);
    console.log('0으로는 나눌 수 없다!');
}

// snack 없음!
// 0으로는 나눌 수 없다!
```

자바스크립트는 0으로 나눌 경우 Infinity가 값으로 나온다. 이럴 경우를 대비해 `try-catch` 구문에서 `getSnack` 함수를 호출할 때 throw 구문으로 예외를 정의해놓는다. catch 블록이 존재하기 때문에 종료되지 않고 catch 블록이 실행된다. 아래 MDN 문서를 참고하면 좋다.

[throw - JavaScript | MDN](https://developer.mozilla.org/ko/docs/Web/JavaScript/Reference/Statements/throw)

그 외에도 프로미스 사용시 예외가 발생하는 경우는 앞서 [8. 비동기-프로미스](https://www.notion.so/8-await-async-fetch-835e5806f6be444aa02ccfd38cb7a9b7) 페이지를 참고하면 된다.
